[2025-08-22T04:45:20.950+0000] {local_task_job_runner.py:120} INFO - ::group::Pre task execution logs
[2025-08-22T04:45:20.988+0000] {taskinstance.py:2073} INFO - Dependencies all met for dep_context=non-requeueable deps ti=<TaskInstance: stock_market_db_test.test_db_connection manual__2025-08-22T04:40:14.802406+00:00 [queued]>
[2025-08-22T04:45:20.997+0000] {taskinstance.py:2073} INFO - Dependencies all met for dep_context=requeueable deps ti=<TaskInstance: stock_market_db_test.test_db_connection manual__2025-08-22T04:40:14.802406+00:00 [queued]>
[2025-08-22T04:45:20.999+0000] {taskinstance.py:2303} INFO - Starting attempt 2 of 2
[2025-08-22T04:45:21.016+0000] {taskinstance.py:2327} INFO - Executing <Task(PythonOperator): test_db_connection> on 2025-08-22 04:40:14.802406+00:00
[2025-08-22T04:45:21.024+0000] {standard_task_runner.py:63} INFO - Started process 712 to run task
[2025-08-22T04:45:21.028+0000] {standard_task_runner.py:90} INFO - Running: ['airflow', 'tasks', 'run', 'stock_market_db_test', 'test_db_connection', 'manual__2025-08-22T04:40:14.802406+00:00', '--job-id', '10', '--raw', '--subdir', 'DAGS_FOLDER/stock_market_dag.py', '--cfg-path', '/tmp/tmp_s9slqpe']
[2025-08-22T04:45:21.031+0000] {standard_task_runner.py:91} INFO - Job 10: Subtask test_db_connection
[2025-08-22T04:45:21.092+0000] {task_command.py:426} INFO - Running <TaskInstance: stock_market_db_test.test_db_connection manual__2025-08-22T04:40:14.802406+00:00 [running]> on host c8aa366a6fee
[2025-08-22T04:45:21.195+0000] {taskinstance.py:2644} INFO - Exporting env vars: AIRFLOW_CTX_DAG_OWNER='airflow' AIRFLOW_CTX_DAG_ID='stock_market_db_test' AIRFLOW_CTX_TASK_ID='test_db_connection' AIRFLOW_CTX_EXECUTION_DATE='2025-08-22T04:40:14.802406+00:00' AIRFLOW_CTX_TRY_NUMBER='2' AIRFLOW_CTX_DAG_RUN_ID='manual__2025-08-22T04:40:14.802406+00:00'
[2025-08-22T04:45:21.197+0000] {taskinstance.py:430} INFO - ::endgroup::
[2025-08-22T04:45:21.229+0000] {log.py:232} WARNING - 2025-08-22 04:45:21 - unusual_prefix_29e1818db1245208dbea5bb211ec036ee40040ab_stock_market_dag - ERROR - Failed to initialize database connection pool: connection to server at "***" (172.18.0.3), port 5432 failed: FATAL:  password authentication failed for user "***"
[2025-08-22T04:45:21.229+0000] {stock_market_dag.py:674} ERROR - Failed to initialize database connection pool: connection to server at "***" (172.18.0.3), port 5432 failed: FATAL:  password authentication failed for user "***"

[2025-08-22T04:45:21.231+0000] {taskinstance.py:441} INFO - ::group::Post task execution logs
[2025-08-22T04:45:21.232+0000] {taskinstance.py:2890} ERROR - Task failed with exception
Traceback (most recent call last):
  File "/home/airflow/.local/lib/python3.10/site-packages/airflow/models/taskinstance.py", line 465, in _execute_task
    result = _execute_callable(context=context, **execute_callable_kwargs)
  File "/home/airflow/.local/lib/python3.10/site-packages/airflow/models/taskinstance.py", line 432, in _execute_callable
    return execute_callable(context=context, **execute_callable_kwargs)
  File "/home/airflow/.local/lib/python3.10/site-packages/airflow/models/baseoperator.py", line 400, in wrapper
    return func(self, *args, **kwargs)
  File "/home/airflow/.local/lib/python3.10/site-packages/airflow/operators/python.py", line 235, in execute
    return_value = self.execute_callable()
  File "/home/airflow/.local/lib/python3.10/site-packages/airflow/operators/python.py", line 252, in execute_callable
    return self.python_callable(*self.op_args, **self.op_kwargs)
  File "/opt/airflow/dags/stock_market_dag.py", line 1176, in test_db_connection
    db_manager = DatabaseManager()  # create instance inside the task
  File "/opt/airflow/dags/stock_market_dag.py", line 662, in __init__
    self.pool = psycopg2.pool.ThreadedConnectionPool(
  File "/home/airflow/.local/lib/python3.10/site-packages/psycopg2/pool.py", line 161, in __init__
    AbstractConnectionPool.__init__(
  File "/home/airflow/.local/lib/python3.10/site-packages/psycopg2/pool.py", line 59, in __init__
    self._connect()
  File "/home/airflow/.local/lib/python3.10/site-packages/psycopg2/pool.py", line 63, in _connect
    conn = psycopg2.connect(*self._args, **self._kwargs)
  File "/home/airflow/.local/lib/python3.10/site-packages/psycopg2/__init__.py", line 122, in connect
    conn = _connect(dsn, connection_factory=connection_factory, **kwasync)
psycopg2.OperationalError: connection to server at "***" (172.18.0.3), port 5432 failed: FATAL:  password authentication failed for user "***"

[2025-08-22T04:45:21.253+0000] {taskinstance.py:1205} INFO - Marking task as FAILED. dag_id=stock_market_db_test, task_id=test_db_connection, execution_date=20250822T044014, start_date=20250822T044520, end_date=20250822T044521
[2025-08-22T04:45:21.271+0000] {standard_task_runner.py:110} ERROR - Failed to execute job 10 for task test_db_connection (connection to server at "***" (172.18.0.3), port 5432 failed: FATAL:  password authentication failed for user "***"
; 712)
[2025-08-22T04:45:21.281+0000] {local_task_job_runner.py:240} INFO - Task exited with return code 1
[2025-08-22T04:45:21.302+0000] {taskinstance.py:3482} INFO - 0 downstream tasks scheduled from follow-on schedule check
[2025-08-22T04:45:21.306+0000] {local_task_job_runner.py:222} INFO - ::endgroup::
