[2025-08-22T04:34:16.281+0000] {scheduler_job_runner.py:1737} ERROR - Detected zombie job: {'full_filepath': '/opt/airflow/dags/stock_market_dag.py', 'processor_subdir': '/opt/airflow/dags', 'msg': "{'DAG Id': 'stock_market_db_test', 'Task Id': 'test_db_connection', 'Run Id': 'scheduled__2025-08-21T00:00:00+00:00', 'Hostname': 'c8aa366a6fee', 'External Executor Id': '1b20bf7e-a6e8-4620-8129-31df1ef2d65f'}", 'simple_task_instance': <airflow.models.taskinstance.SimpleTaskInstance object at 0x7f6076363b50>, 'is_failure_callback': True} (See https://airflow.apache.org/docs/apache-airflow/stable/core-concepts/tasks.html#zombie-undead-tasks)
[2025-08-22T04:34:26.452+0000] {scheduler_job_runner.py:1737} ERROR - Detected zombie job: {'full_filepath': '/opt/airflow/dags/stock_market_dag.py', 'processor_subdir': '/opt/airflow/dags', 'msg': "{'DAG Id': 'stock_market_db_test', 'Task Id': 'test_db_connection', 'Run Id': 'scheduled__2025-08-21T00:00:00+00:00', 'Hostname': 'c8aa366a6fee', 'External Executor Id': '1b20bf7e-a6e8-4620-8129-31df1ef2d65f'}", 'simple_task_instance': <airflow.models.taskinstance.SimpleTaskInstance object at 0x7f60763b52a0>, 'is_failure_callback': True} (See https://airflow.apache.org/docs/apache-airflow/stable/core-concepts/tasks.html#zombie-undead-tasks)
[2025-08-22T15:31:00.025+0000] {scheduler_job_runner.py:769} ERROR - Executor reports task instance <TaskInstance: stock_market_db_test.test_db_connection scheduled__2025-08-21T00:00:00+00:00 [queued]> finished (failed) although the task says it's queued. (Info: None) Was the task killed externally?
