[2025-08-22T15:29:10.853+0000] {local_task_job_runner.py:120} INFO - ::group::Pre task execution logs
[2025-08-22T15:29:10.947+0000] {taskinstance.py:2073} INFO - Dependencies all met for dep_context=non-requeueable deps ti=<TaskInstance: fetch_stock_data.fetch_and_store_stock_data scheduled__2025-08-21T00:00:00+00:00 [queued]>
[2025-08-22T15:29:10.973+0000] {taskinstance.py:2073} INFO - Dependencies all met for dep_context=requeueable deps ti=<TaskInstance: fetch_stock_data.fetch_and_store_stock_data scheduled__2025-08-21T00:00:00+00:00 [queued]>
[2025-08-22T15:29:10.975+0000] {taskinstance.py:2303} INFO - Starting attempt 1 of 2
[2025-08-22T15:29:11.009+0000] {taskinstance.py:2327} INFO - Executing <Task(PythonOperator): fetch_and_store_stock_data> on 2025-08-21 00:00:00+00:00
[2025-08-22T15:29:11.027+0000] {standard_task_runner.py:63} INFO - Started process 52 to run task
[2025-08-22T15:29:11.060+0000] {standard_task_runner.py:90} INFO - Running: ['***', 'tasks', 'run', 'fetch_stock_data', 'fetch_and_store_stock_data', 'scheduled__2025-08-21T00:00:00+00:00', '--job-id', '3', '--raw', '--subdir', 'DAGS_FOLDER/fetch_stock_data.py', '--cfg-path', '/tmp/tmptd8fkkw0']
[2025-08-22T15:29:11.102+0000] {standard_task_runner.py:91} INFO - Job 3: Subtask fetch_and_store_stock_data
[2025-08-22T15:29:11.346+0000] {task_command.py:426} INFO - Running <TaskInstance: fetch_stock_data.fetch_and_store_stock_data scheduled__2025-08-21T00:00:00+00:00 [running]> on host e557fe80712b
[2025-08-22T15:29:11.677+0000] {taskinstance.py:2644} INFO - Exporting env vars: AIRFLOW_CTX_DAG_OWNER='***' AIRFLOW_CTX_DAG_ID='fetch_stock_data' AIRFLOW_CTX_TASK_ID='fetch_and_store_stock_data' AIRFLOW_CTX_EXECUTION_DATE='2025-08-21T00:00:00+00:00' AIRFLOW_CTX_TRY_NUMBER='1' AIRFLOW_CTX_DAG_RUN_ID='scheduled__2025-08-21T00:00:00+00:00'
[2025-08-22T15:29:11.684+0000] {taskinstance.py:430} INFO - ::endgroup::
[2025-08-22T15:30:58.821+0000] {taskinstance.py:441} INFO - ::group::Post task execution logs
[2025-08-22T15:30:58.831+0000] {taskinstance.py:2890} ERROR - Task failed with exception
Traceback (most recent call last):
  File "/home/airflow/.local/lib/python3.10/site-packages/urllib3/connectionpool.py", line 715, in urlopen
    httplib_response = self._make_request(
  File "/home/airflow/.local/lib/python3.10/site-packages/urllib3/connectionpool.py", line 467, in _make_request
    six.raise_from(e, None)
  File "<string>", line 3, in raise_from
  File "/home/airflow/.local/lib/python3.10/site-packages/urllib3/connectionpool.py", line 462, in _make_request
    httplib_response = conn.getresponse()
  File "/usr/local/lib/python3.10/http/client.py", line 1375, in getresponse
    response.begin()
  File "/usr/local/lib/python3.10/http/client.py", line 318, in begin
    version, status, reason = self._read_status()
  File "/usr/local/lib/python3.10/http/client.py", line 287, in _read_status
    raise RemoteDisconnected("Remote end closed connection without"
http.client.RemoteDisconnected: Remote end closed connection without response

During handling of the above exception, another exception occurred:

Traceback (most recent call last):
  File "/home/airflow/.local/lib/python3.10/site-packages/requests/adapters.py", line 486, in send
    resp = conn.urlopen(
  File "/home/airflow/.local/lib/python3.10/site-packages/urllib3/connectionpool.py", line 799, in urlopen
    retries = retries.increment(
  File "/home/airflow/.local/lib/python3.10/site-packages/urllib3/util/retry.py", line 550, in increment
    raise six.reraise(type(error), error, _stacktrace)
  File "/home/airflow/.local/lib/python3.10/site-packages/urllib3/packages/six.py", line 769, in reraise
    raise value.with_traceback(tb)
  File "/home/airflow/.local/lib/python3.10/site-packages/urllib3/connectionpool.py", line 715, in urlopen
    httplib_response = self._make_request(
  File "/home/airflow/.local/lib/python3.10/site-packages/urllib3/connectionpool.py", line 467, in _make_request
    six.raise_from(e, None)
  File "<string>", line 3, in raise_from
  File "/home/airflow/.local/lib/python3.10/site-packages/urllib3/connectionpool.py", line 462, in _make_request
    httplib_response = conn.getresponse()
  File "/usr/local/lib/python3.10/http/client.py", line 1375, in getresponse
    response.begin()
  File "/usr/local/lib/python3.10/http/client.py", line 318, in begin
    version, status, reason = self._read_status()
  File "/usr/local/lib/python3.10/http/client.py", line 287, in _read_status
    raise RemoteDisconnected("Remote end closed connection without"
urllib3.exceptions.ProtocolError: ('Connection aborted.', RemoteDisconnected('Remote end closed connection without response'))

During handling of the above exception, another exception occurred:

Traceback (most recent call last):
  File "/home/airflow/.local/lib/python3.10/site-packages/airflow/models/taskinstance.py", line 465, in _execute_task
    result = _execute_callable(context=context, **execute_callable_kwargs)
  File "/home/airflow/.local/lib/python3.10/site-packages/airflow/models/taskinstance.py", line 432, in _execute_callable
    return execute_callable(context=context, **execute_callable_kwargs)
  File "/home/airflow/.local/lib/python3.10/site-packages/airflow/models/baseoperator.py", line 400, in wrapper
    return func(self, *args, **kwargs)
  File "/home/airflow/.local/lib/python3.10/site-packages/airflow/operators/python.py", line 235, in execute
    return_value = self.execute_callable()
  File "/home/airflow/.local/lib/python3.10/site-packages/airflow/operators/python.py", line 252, in execute_callable
    return self.python_callable(*self.op_args, **self.op_kwargs)
  File "/opt/airflow/dags/fetch_stock_data.py", line 32, in fetch_and_store
    response = requests.get(url)
  File "/home/airflow/.local/lib/python3.10/site-packages/requests/api.py", line 73, in get
    return request("get", url, params=params, **kwargs)
  File "/home/airflow/.local/lib/python3.10/site-packages/requests/api.py", line 59, in request
    return session.request(method=method, url=url, **kwargs)
  File "/home/airflow/.local/lib/python3.10/site-packages/requests/sessions.py", line 589, in request
    resp = self.send(prep, **send_kwargs)
  File "/home/airflow/.local/lib/python3.10/site-packages/requests/sessions.py", line 703, in send
    r = adapter.send(request, **kwargs)
  File "/home/airflow/.local/lib/python3.10/site-packages/requests/adapters.py", line 501, in send
    raise ConnectionError(err, request=request)
requests.exceptions.ConnectionError: ('Connection aborted.', RemoteDisconnected('Remote end closed connection without response'))
[2025-08-22T15:30:59.161+0000] {taskinstance.py:1205} INFO - Marking task as UP_FOR_RETRY. dag_id=fetch_stock_data, task_id=fetch_and_store_stock_data, execution_date=20250821T000000, start_date=20250822T152910, end_date=20250822T153059
[2025-08-22T15:30:59.308+0000] {standard_task_runner.py:110} ERROR - Failed to execute job 3 for task fetch_and_store_stock_data (('Connection aborted.', RemoteDisconnected('Remote end closed connection without response')); 52)
[2025-08-22T15:30:59.523+0000] {local_task_job_runner.py:240} INFO - Task exited with return code 1
[2025-08-22T15:30:59.664+0000] {taskinstance.py:3482} INFO - 0 downstream tasks scheduled from follow-on schedule check
[2025-08-22T15:30:59.675+0000] {local_task_job_runner.py:222} INFO - ::endgroup::
